Workbook

Sheet Panel
B1: Panel · Sistema de Gestión MP 2026
B2: Pulso del equipamiento clínico — HHHA · se actualiza al abrir en Excel
B3: Hoy: | C3: =TODAY() -> 46191
B5: OPERATIVIDAD (hoy)
B6: Casos abiertos | C6: Equipos No Operativos | D6: En servicio técnico | E6: Dados de baja | F6: Pend. documentales
B7: =COUNTIF('1. Órdenes de Trabajo'!$J$2:$J$301,"Abierto") -> 11 | C7: =COUNTIFS('1. Órdenes de Trabajo'!$J$2:$J$301,"Abierto",'1. Órdenes de Trabajo'!$H$2:$H$301,"No Operativo") -> 11 | D7: =SUMPRODUCT(('5. Servicio Técnico (Envíos)'!$A$2:$A$301<>"")*('5. Servicio Técnico (Envíos)'!$K$2:$K$301<>"Operativo")) -> 8 | E7: =COUNTIF('6. Bajas'!$A$2:$A$301,"?*") -> 0 | F7: =COUNTIF('4. Visitas Técnicas'!$L$2:$L$301,"No")+COUNTIF('5. Servicio Técnico (Envíos)'!$M$2:$M$301,"No") -> 2
B9: PROGRAMA PREVENTIVO 2026
B10: MP programadas | C10: MP ejecutadas | D10: % avance | E10: Reprogramadas | F10: Por correctivo
B11: =SUM('MP Carta 2026'!$U$4:$U$969) -> 1258 | C11: =SUM('MP Carta 2026'!$V$4:$V$969) -> 784 | D11: =IFERROR(SUM('MP Carta 2026'!$V$4:$V$969)/SUM('MP Carta 2026'!$U$4:$U$969),"") -> 0.62321145 | E11: =SUMPRODUCT(--('MP Carta 2026'!$I$4:$T$969="R")) -> 269 | F11: =SUM('MP Carta 2026'!$X$4:$X$969) -> 41
B13: PENDIENTES (cola de acción)
B14: Por hacer | C14: Vencidos | D14: Completados
B15: =COUNTIF(Pendientes!$H$2:$H$200,"Por hacer") -> 32 | C15: =COUNTIFS(Pendientes!$H$2:$H$200,"Por hacer",Pendientes!$G$2:$G$200,"Vencido") -> 12 | D15: =COUNTIF(Pendientes!$H$2:$H$200,"Completado") -> 0
B17: EQUIPOS CRÍTICOS — en correctivo + preventivo + pendientes
B18: N° Inventario | C18: Equipo | D18: Servicio | E18: Caso abierto | F18: Pend. por hacer
B19: 2-013590 | C19: =IFERROR(VLOOKUP($B19,Equipos!$C$2:$D$967,2,FALSE()),"") -> Ventilador Mecánico | D19: =IFERROR(VLOOKUP($B19,Equipos!$C$2:$F$967,3,FALSE()),"") -> UPC Adulto | E19: =IF(COUNTIFS('1. Órdenes de Trabajo'!$F$2:$F$301,$B19,'1. Órdenes de Trabajo'!$J$2:$J$301,"Abierto")>0,"Sí","No") -> Sí | F19: =COUNTIFS(Pendientes!$C$2:$C$200,$B19,Pendientes!$H$2:$H$200,"Por hacer") -> 3
B20: 2-110571 | C20: =IFERROR(VLOOKUP($B20,Equipos!$C$2:$D$967,2,FALSE()),"") -> Ventilador Mecánico | D20: =IFERROR(VLOOKUP($B20,Equipos!$C$2:$F$967,3,FALSE()),"") -> UPC Adulto | E20: =IF(COUNTIFS('1. Órdenes de Trabajo'!$F$2:$F$301,$B20,'1. Órdenes de Trabajo'!$J$2:$J$301,"Abierto")>0,"Sí","No") -> No | F20: =COUNTIFS(Pendientes!$C$2:$C$200,$B20,Pendientes!$H$2:$H$200,"Por hacer") -> 2
B21: 2-119890 | C21: =IFERROR(VLOOKUP($B21,Equipos!$C$2:$D$967,2,FALSE()),"") -> Ventilador Mecánico | D21: =IFERROR(VLOOKUP($B21,Equipos!$C$2:$F$967,3,FALSE()),"") -> UPC 3er Piso | E21: =IF(COUNTIFS('1. Órdenes de Trabajo'!$F$2:$F$301,$B21,'1. Órdenes de Trabajo'!$J$2:$J$301,"Abierto")>0,"Sí","No") -> Sí | F21: =COUNTIFS(Pendientes!$C$2:$C$200,$B21,Pendientes!$H$2:$H$200,"Por hacer") -> 0
B22: 2-119891 | C22: =IFERROR(VLOOKUP($B22,Equipos!$C$2:$D$967,2,FALSE()),"") -> Ventilador Mecánico | D22: =IFERROR(VLOOKUP($B22,Equipos!$C$2:$F$967,3,FALSE()),"") -> UPC 3er Piso | E22: =IF(COUNTIFS('1. Órdenes de Trabajo'!$F$2:$F$301,$B22,'1. Órdenes de Trabajo'!$J$2:$J$301,"Abierto")>0,"Sí","No") -> Sí | F22: =COUNTIFS(Pendientes!$C$2:$C$200,$B22,Pendientes!$H$2:$H$200,"Por hacer") -> 0
B23: 2-121203 | C23: =IFERROR(VLOOKUP($B23,Equipos!$C$2:$D$967,2,FALSE()),"") -> Ventilador Mecánico | D23: =IFERROR(VLOOKUP($B23,Equipos!$C$2:$F$967,3,FALSE()),"") -> UPC 3er Piso | E23: =IF(COUNTIFS('1. Órdenes de Trabajo'!$F$2:$F$301,$B23,'1. Órdenes de Trabajo'!$J$2:$J$301,"Abierto")>0,"Sí","No") -> Sí | F23: =COUNTIFS(Pendientes!$C$2:$C$200,$B23,Pendientes!$H$2:$H$200,"Por hacer") -> 0
B26: IR A:
B27: =HYPERLINK("#Pendientes!A1","▸ Pendientes (qué hacer hoy)") -> ▸ Pendientes (qué hacer hoy)
B28: =HYPERLINK("#'Ficha de Equipo'!A1","▸ Ficha de Equipo (estado 360)") -> ▸ Ficha de Equipo (estado 360)
B29: =HYPERLINK("#Tablero!A1","▸ Tablero correctivo") -> ▸ Tablero correctivo
B30: =HYPERLINK("#'MP Carta 2026'!A1","▸ MP Carta 2026") -> ▸ MP Carta 2026
B33: CONCILIACIÓN — MATRIZ ↔ BITÁCORA
B34: MP Carta (matriz) vs Registro MP (bitácora) · se actualiza al abrir · Ejec: E↔Sí · No ejec: C2/C3 · Reprog: R↔C1/C5–C8 · Baja: B↔Baja
B36: RESULTADO GLOBAL
B37: =IF(SUMPRODUCT(--($E$40:$E$43<>0))=0,"✓ Matriz y bitácora cuadran","⚠ "&SUMPRODUCT(--($E$40:$E$43<>0))&" categoría(s) descuadrada(s) — revisar registros") -> ⚠ 3 categoría(s) descuadrada(s) — revisar registros
B39: Categoría | C39: MP Carta | D39: Registro MP | E39: Δ | F39: Estado
B40: Ejecutadas | C40: =COUNTIF('MP Carta 2026'!$I$4:$T$969,"E") -> 784 | D40: =COUNTIF('Registro MP'!$J$2:$J$1243,"Sí") -> 785 | E40: =C40-D40 -> -1 | F40: =IF(E40=0,"✓ cuadra","⚠ Δ "&TEXT(E40,"+0;-0")) -> ⚠ Δ -1
B41: No ejec. x falla | C41: =COUNTIF('MP Carta 2026'!$I$4:$T$969,"C2")+COUNTIF('MP Carta 2026'!$I$4:$T$969,"C3") -> 41 | D41: =COUNTIF('Registro MP'!$J$2:$J$1243,"C2")+COUNTIF('Registro MP'!$J$2:$J$1243,"C3") -> 42 | E41: =C41-D41 -> -1 | F41: =IF(E41=0,"✓ cuadra","⚠ Δ "&TEXT(E41,"+0;-0")) -> ⚠ Δ -1
B42: Reprogramadas | C42: =COUNTIF('MP Carta 2026'!$I$4:$T$969,"R") -> 269 | D42: =COUNTIF('Registro MP'!$J$2:$J$1243,"C1")+COUNTIF('Registro MP'!$J$2:$J$1243,"C5")+COUNTIF('Registro MP'!$J$2:$J$1243,"C6")+COUNTIF('Registro MP'!$J$2:$J$1243,"C7")+COUNTIF('Registro MP'!$J$2:$J$1243,"C8") -> 266 | E42: =C42-D42 -> 3 | F42: =IF(E42=0,"✓ cuadra","⚠ Δ "&TEXT(E42,"+0;-0")) -> ⚠ Δ +3
B43: Bajas | C43: =COUNTIF('MP Carta 2026'!$I$4:$T$969,"B") -> 6 | D43: =COUNTIF('Registro MP'!$J$2:$J$1243,"Baja") -> 6 | E43: =C43-D43 -> 0 | F43: =IF(E43=0,"✓ cuadra","⚠ Δ "&TEXT(E43,"+0;-0")) -> ✓ cuadra
B45: Solo en bitácora (No/NU, sin slot en matriz): | D45: =COUNTIF('Registro MP'!$J$2:$J$1243,"No")+COUNTIF('Registro MP'!$J$2:$J$1243,"NU") -> 5

Sheet Pendientes
A1: Equipo | B1: Serie | C1: N° Inventario | D1: Tipo de pendiente | E1: Fecha compromiso | F1: Días de atraso | G1: Situación | H1: Estado | I1: Prioridad | J1: Responsable Ejecutivo | K1: Responsable Administrativo | L1: En espera de | M1: Descripción | N1: Tareas | O1: Fecha completado | P1: Creado
A2: DEA | B2: X21J421750 | C2: 121010-020241 | D2: Pauta de Monitoreo Diario | E2: 46188 | G2: Resuelto | H2: Hecho | I2: Media | J2: Carlos Bahamondes Seguel | K2: Cristián Beltrán Oviedo | M2: Pauta de monitoreo diario Enero hasta Abril | N2: — | O2: 46181
A3: DEA | B3: 122002985 | C3: 2-001551 | D3: Pauta de Monitoreo Diario | E3: 46202 | G3: Resuelto | H3: Hecho | I3: Media | J3: Carlos Bahamondes Seguel | K3: Cristián Beltrán Oviedo | M3: Pauta de monitoreo enero, febrero, abril y mayo | N3: — | O3: 46181
A4: DEA | B4: 40361 | C4: 2-134461 | D4: Pauta de Monitoreo Diario | E4: 46202 | G4: Vigente | H4: En proceso | I4: Media | J4: Carlos Bahamondes Seguel | K4: Cristián Beltrán Oviedo | M4: Pauta de monitoreo Enero, Febrero,, Marzo, Abril, Mayo | N4: —
A5: DEA | B5: 13036 | C5: 121010-019243 | D5: Pauta de Monitoreo Diario | E5: 46202 | G5: Resuelto | H5: Hecho | I5: Media | J5: Carlos Bahamondes Seguel | K5: Cristián Beltrán Oviedo | M5: Pauta de monitoreo diario meses noviembre, diciembre (2025) enero, febrero, marzo, abril (2026) | N5: — | O5: 46181
A6: DEA | B6: X21A332744 | C6: 2-121624 | D6: Pauta de Monitoreo Diario | E6: 46171 | F6: 20 | G6: Vencido | H6: En proceso | I6: Media | J6: Carlos Bahamondes Seguel | K6: Cristián Beltrán Oviedo | M6: Pauta de monitoreo | N6: —
A7: DEA | B7: 122002994 | C7: 2-112273 | D7: Pauta de Monitoreo Diario | E7: 46188 | G7: Resuelto | H7: Hecho | I7: Media | J7: Carlos Bahamondes Seguel | K7: Cristián Beltrán Oviedo | M7: Pauta de monitoreo diario enero y febrero | N7: — | O7: 46181
A8: DEA | B8: AE7-24048210 | C8: 2-124605 | D8: Pauta de Monitoreo Diario | E8: 46175 | F8: 16 | G8: Vencido | H8: En proceso | I8: Media | J8: Carlos Bahamondes Seguel | K8: Cristián Beltrán Oviedo | M8: Pauta de monitoreo diario | N8: —
A9: DEA | B9: 40422 | C9: 2-134460 | D9: Pauta de Monitoreo Diario | E9: 46182 | F9: 9 | G9: Vencido | H9: En proceso | I9: Media | J9: Carlos Bahamondes Seguel | K9: Cristián Beltrán Oviedo | M9: Pauta de monitoreo diario abril | N9: —
A10: DEA | B10: 122003001 | C10: 2-112274 | D10: Pauta de Monitoreo Diario | E10: 46188 | G10: Resuelto | H10: Hecho | I10: Media | J10: Carlos Bahamondes Seguel | K10: Cristián Beltrán Oviedo | M10: pauta de monitoreo diario de enero, febreo, abril y mayo | N10: — | O10: 46181
A11: DEA | B11: 122002995 | C11: 2-112275 | D11: Documento faltante | E11: 46188 | G11: Resuelto | H11: Hecho | I11: Media | J11: Carlos Bahamondes Seguel | K11: Cristián Beltrán Oviedo | M11: Pauta de monitoreo diario abril y mayo | N11: — | O11: 46181
A12: DEA | B12: 122003000 | C12: 2-112276 | D12: Pauta de Monitoreo Diario | E12: 46188 | G12: Resuelto | H12: Hecho | I12: Media | J12: Carlos Bahamondes Seguel | K12: Cristián Beltrán Oviedo | M12: paura de monitoreo diario de enero, febreo, abril y mayo | N12: — | O12: 46181
A13: DEA | B13: 122002981 | C13: 2-112277 | D13: Pauta de Monitoreo Diario | E13: 46188 | G13: Resuelto | H13: Hecho | I13: Media | J13: Carlos Bahamondes Seguel | K13: Cristián Beltrán Oviedo | M13: pauta de monitoreo diario de enero, febrero, abril y mayo | N13: — | O13: 46181
A14: DEA | B14: 122002988 | C14: 2-112278 | D14: Documento faltante | E14: 46175 | G14: Resuelto | H14: Hecho | I14: Media | J14: Carlos Bahamondes Seguel | K14: Cristián Beltrán Oviedo | M14: pauta de monitoreo diario de enero, febrero, abril y mayo | N14: — | O14: 46181
A15: Desfibrilador | B15: 40979213 | C15: 2-024418 | D15: Gestión general | E15: 46175 | F15: 16 | G15: Vencido | H15: Por hacer | I15: Media | K15: Cristián Beltrán Oviedo | M15: Solicitar al servicio que haga la solicitud de trabajo e informar | N15: —
A16: Monitor Multiparámetros | B16: CN12099174 | C16: 2-126872 | D16: Reprogramación MP | E16: 46168 | F16: 23 | G16: Vencido | H16: Por hacer | I16: Media | J16: Cristián Beltrán Oviedo | K16: Cristián Beltrán Oviedo | M16: Sacar reprogramación, MP le correspondia en Abril | N16: —
A17: DEA | B17: AF1-48110851 | C17: 2-134465 | D17: Pauta de Monitoreo Diario | E17: 46175 | F17: 16 | G17: Vencido | H17: En proceso | I17: Media | J17: Carlos Bahamondes Seguel | K17: Cristián Beltrán Oviedo | M17: Pauta de monitoreo diario Abril | N17: —
A18: DEA | B18: X18E028657 | C18: 2-117973 | D18: Pauta de Monitoreo Diario | E18: 46175 | F18: 16 | G18: Vencido | H18: En proceso | I18: Media | J18: Carlos Bahamondes Seguel | K18: Cristián Beltrán Oviedo | M18: Pauta de monitoreo diario | N18: —
A19: Ventilador Mecánico | B19: 3512202231 | C19: 200717-005511 | D19: Documento faltante | E19: 46169 | G19: Resuelto | H19: Hecho | I19: Media | J19: Cristián Beltrán Oviedo | K19: Cristián Beltrán Oviedo | M19: Falta firma del servicio clinico | N19: — | O19: 46176
A20: Máquina de Anestesia | B20: ASMB-0231 | C20: 2-117816 | D20: Gestión general | E20: 46175 | F20: 16 | G20: Vencido | H20: Por hacer | I20: Media | J20: Cristina Rozas Urrutia | K20: Cristián Beltrán Oviedo | M20: Consultar estado | N20: —
A21: Máquina de Anestesia | B21: ASMB-0231 | C21: 2-117816 | D21: Reprogramación MP | G21: Vigente | H21: Por hacer | I21: Media | J21: Marco Ulloa | K21: Cristián Beltrán Oviedo | M21: Reprogramar MP por causal C3 — Equipo no operativo, a la espera de repuestos o accesorios. Sin fecha definida, depende del reintegro del equipo al servicio. | N21: —
A22: Máquina de Anestesia | B22: ASMB-0231 | C22: 2-117816 | D22: Reprogramación MP | G22: Vigente | H22: Por hacer | I22: Media | J22: Cristina Rozas Urrutia | K22: Cristián Beltrán Oviedo | M22: Reprogramar MP por causal C3 — Equipo no operativo, a la espera de repuestos o accesorios. Sin fecha definida, depende del reintegro del equipo al servicio. | N22: —
A23: Máquina de Anestesia | B23: ASMB-0230 | C23: 2-117815 | D23: Gestión general | G23: Vigente | H23: Por hacer | I23: Media | K23: Cristián Beltrán Oviedo | M23: Durante mantención preventiva se instala repuesto de freno, sin embargo, queda pendiente instalación de pieza en custodia de cliente | N23: —
A24: Máquina de Anestesia | B24: ARYA-0174 | C24: 2-017350 | D24: Gestión general | G24: Vigente | H24: Por hacer | I24: Media | K24: Cristián Beltrán Oviedo | M24: Cotizar repuestos para las reparaciones | N24: —
A25: Máquina de Anestesia | B25: ARYA-0174 | C25: 2-017350 | D25: Gestión general | G25: Vigente | H25: Por hacer | I25: Media | K25: Cristián Beltrán Oviedo | M25: Reparar sistema interlock (instalación de barra intermedia) | N25: —
A26: Monitor Multiparámetros | B26: 22060100003 | C26: 2-124762 | D26: Documento faltante | E26: 46176 | G26: Resuelto | H26: Hecho | I26: Media | J26: Daniel Díaz Neira | K26: Cristián Beltrán Oviedo | M26: Entregado a daniel, falta la firma de marco | N26: — | O26: 46174
A27: Monitor Multiparámetros | B27: PSHH501479 | C27: 2-121002 | D27: Documento faltante | E27: 46176 | G27: Resuelto | H27: Hecho | I27: Media | J27: Daniel Díaz Neira | K27: Cristián Beltrán Oviedo | M27: entregado a daniel, falta firma de marco | N27: — | O27: 46174
A28: Monitor Multiparámetros | B28: PSHH501479 | C28: 2-121002 | D28: Reprogramación MP | E28: 46173 | G28: Resuelto | H28: Hecho | I28: Media | J28: Daniel Díaz Neira | K28: Cristián Beltrán Oviedo | M28: Reprogramar MP por causal C8 — Contingencia hospitalaria. Reprogramación dentro del mes siguiente (norma PMP). | N28: — | O28: 46174
A29: Monitor Multiparámetros | B29: G3HQ40045 | C29: 2-118718 | D29: Documento faltante | E29: 46176 | G29: Resuelto | H29: Hecho | I29: Media | J29: Daniel Díaz Neira | K29: Cristián Beltrán Oviedo | M29: documento entregado a daniel, falta la firma de marco | N29: — | O29: 46174
A30: Monitor Multiparámetros | B30: G3HQ40045 | C30: 2-118718 | D30: Reprogramación MP | E30: 46173 | G30: Resuelto | H30: Hecho | I30: Media | J30: Daniel Díaz Neira | K30: Cristián Beltrán Oviedo | M30: Reprogramar MP por causal C8 — Contingencia hospitalaria. Reprogramación dentro del mes siguiente (norma PMP). | N30: — | O30: 46174
A31: DEA | B31: X18E028657 | C31: 2-117973 | D31: Gestión general | E31: 46174 | F31: 17 | G31: Vencido | H31: Por hacer | I31: Media | J31: Cristián Beltrán Oviedo | K31: Cristián Beltrán Oviedo | M31: Cambiar la etiqueta de la carpeta, no tiene el numero de inventario | N31: —
A32: Ventilador Mecánico | B32: ASHK-0151 | C32: 2-110571 | D32: Reprogramación MP | E32: 46175 | F32: 16 | G32: Vencido | H32: Por hacer | I32: Media | J32: Cristián Beltrán Oviedo | K32: Cristián Beltrán Oviedo | M32: Sacar reprogramación revisar si corresponde C6 o no porque quizás estaba en servicio tecnico | N32: —
A33: Ventilador Mecánico | B33: ASNM-0003 | C33: 2-120946 | D33: Reprogramación MP | E33: 46170 | F33: 21 | G33: Vencido | H33: Por hacer | I33: Media | J33: Cristián Beltrán Oviedo | K33: Cristián Beltrán Oviedo | M33: Abril, causal c6 | N33: —
A34: Ventilador Mecánico | B34: ASNM-0005 | C34: 2-120943 | D34: Reprogramación MP | E34: 46175 | F34: 16 | G34: Vencido | H34: Por hacer | I34: Media | J34: Cristián Beltrán Oviedo | K34: Cristián Beltrán Oviedo | M34: REPROGRAMACION CAUSAL C6 | N34: —
A35: Ventilador Mecánico | B35: ASFN-0006 | C35: 2-013592 | D35: Reprogramación MP | E35: 46201 | G35: Vigente | H35: Por hacer | I35: Media | J35: Ricardo Matus Aroca | K35: Cristián Beltrán Oviedo | M35: Reprogramar MP por causal C6 — No disponibilidad de HH servicio técnico externo. Reprogramar dentro de 30 días. | N35: —
A36: Ventilador Mecánico | B36: ASFN-0008 | C36: 2-013590 | D36: Gestión general | G36: Resuelto | H36: Hecho | I36: Media | J36: Cristián Beltrán Oviedo | K36: Cristián Beltrán Oviedo | M36: Firma de marco | N36: — | O36: 46174
A37: Ventilador Mecánico | B37: ASKK-0200 | C37: 2-116292 | D37: Gestión general | G37: Resuelto | H37: Hecho | I37: Media | J37: Marco Ulloa | K37: Cristián Beltrán Oviedo | M37: firma marco ulloa | N37: — | O37: 46176
A38: Ventilador Mecánico | B38: ASKL-0007 | C38: 2-116300 | D38: Gestión general | G38: Resuelto | H38: Hecho | I38: Media | J38: Marco Ulloa | K38: Cristián Beltrán Oviedo | M38: Firma marco | N38: — | O38: 46174
A39: Ventilador Mecánico | B39: ASFN-0009 | C39: 2-112327 | D39: Reprogramación MP | E39: 46201 | G39: Vigente | H39: Por hacer | I39: Media | J39: Ricardo Matus Aroca | K39: Cristián Beltrán Oviedo | M39: Reprogramar MP por causal C6 — No disponibilidad de HH servicio técnico externo. Reprogramar dentro de 30 días. | N39: —
A40: Monitor Multiparámetros | B40: 5494528944 | C40: 2-024297 | D40: Reprogramación MP | E40: 46174 | G40: Resuelto | H40: Hecho | I40: Media | J40: Cristina Rozas Urrutia | K40: Cristián Beltrán Oviedo | M40: le tocaba en abril pero se hizo en mayo porqué? | N40: — | O40: 46175
...

Sheet Ficha de Equipo
B1: Ficha de Equipo
B2: Elige el N° de inventario y verás todo su estado e historial
B4: N° Inventario: | C4: 2-118732
B6: IDENTIDAD
C7: Equipo | D7: Servicio | E7: Ubicación
C8: =IFERROR(VLOOKUP($C$4,Equipos!$C$2:$M$967,2,FALSE()),"—") -> Monitor Multiparámetros | D8: =IFERROR(VLOOKUP($C$4,Equipos!$C$2:$M$967,3,FALSE()),"—") -> Pabellón Quirúrgico | E8: =IFERROR(VLOOKUP($C$4,Equipos!$C$2:$M$967,5,FALSE()),"—") -> Pabellón 7
C9: Marca | D9: Modelo | E9: Serie
C10: =IFERROR(VLOOKUP($C$4,Equipos!$C$2:$M$967,7,FALSE()),"—") -> Drager | D10: =IFERROR(VLOOKUP($C$4,Equipos!$C$2:$M$967,8,FALSE()),"—") -> M540 | E10: =IFERROR(VLOOKUP($C$4,Equipos!$C$2:$M$967,9,FALSE()),"—") -> 5613543568
B12: ESTADO ACTUAL
B13: ¿Caso correctivo abierto? | D13: =IF(COUNTIFS('1. Órdenes de Trabajo'!$F$2:$F$301,$C$4,'1. Órdenes de Trabajo'!$J$2:$J$301,"Abierto")>0,"SÍ — en proceso","No") -> SÍ — en proceso
B14: ¿En servicio técnico? | D14: =IF(SUMPRODUCT(('5. Servicio Técnico (Envíos)'!$C$2:$C$301=$C$4)*('5. Servicio Técnico (Envíos)'!$K$2:$K$301<>"Operativo"))>0,"Sí","No") -> No
B15: Pendientes por hacer | D15: =COUNTIFS(Pendientes!$C$2:$C$200,$C$4,Pendientes!$H$2:$H$200,"Por hacer") -> 0
B16: MP ejecutadas / programadas | D16: =IFERROR(VLOOKUP($C$4,'MP Carta 2026'!$A$4:$Z$969,22,FALSE())&" / "&VLOOKUP($C$4,'MP Carta 2026'!$A$4:$Z$969,21,FALSE()),"—") -> 1 / 1
B18: PREVENTIVO 2026 (por mes)
B19: Ene | C19: Feb | D19: Mar | E19: Abr | F19: May | G19: Jun
B20: =IFERROR(VLOOKUP($C$4,'MP Carta 2026'!$A$4:$T$969,9,FALSE()),"") -> 0 | C20: =IFERROR(VLOOKUP($C$4,'MP Carta 2026'!$A$4:$T$969,10,FALSE()),"") -> 0 | D20: =IFERROR(VLOOKUP($C$4,'MP Carta 2026'!$A$4:$T$969,11,FALSE()),"") -> 0 | E20: =IFERROR(VLOOKUP($C$4,'MP Carta 2026'!$A$4:$T$969,12,FALSE()),"") -> E | F20: =IFERROR(VLOOKUP($C$4,'MP Carta 2026'!$A$4:$T$969,13,FALSE()),"") -> 0 | G20: =IFERROR(VLOOKUP($C$4,'MP Carta 2026'!$A$4:$T$969,14,FALSE()),"") -> 0
B21: Jul | C21: Ago | D21: Sep | E21: Oct | F21: Nov | G21: Dic
B22: =IFERROR(VLOOKUP($C$4,'MP Carta 2026'!$A$4:$T$969,15,FALSE()),"") -> 0 | C22: =IFERROR(VLOOKUP($C$4,'MP Carta 2026'!$A$4:$T$969,16,FALSE()),"") -> 0 | D22: =IFERROR(VLOOKUP($C$4,'MP Carta 2026'!$A$4:$T$969,17,FALSE()),"") -> 0 | E22: =IFERROR(VLOOKUP($C$4,'MP Carta 2026'!$A$4:$T$969,18,FALSE()),"") -> 0 | F22: =IFERROR(VLOOKUP($C$4,'MP Carta 2026'!$A$4:$T$969,19,FALSE()),"") -> 0 | G22: =IFERROR(VLOOKUP($C$4,'MP Carta 2026'!$A$4:$T$969,20,FALSE()),"") -> 0
B24: HISTORIAL CORRECTIVO
B25: Folio | C25: Fecha OT | D25: Requerimiento | E25: Estado | F25: Cierre
B26: =IFERROR(INDEX('1. Órdenes de Trabajo'!$A$2:$A$301,$T26),"") | C26: =IFERROR(INDEX('1. Órdenes de Trabajo'!$B$2:$B$301,$T26),"") | D26: =IFERROR(INDEX('1. Órdenes de Trabajo'!$D$2:$D$301,$T26),"") | E26: =IFERROR(INDEX('1. Órdenes de Trabajo'!$J$2:$J$301,$T26),"") | F26: =IFERROR(INDEX('1. Órdenes de Trabajo'!$K$2:$K$301,$T26),"") | T26: =IFERROR(_xludf.aggregate(15,6,(ROW('1. Órdenes de Trabajo'!$F$2:$F$301)-ROW('1. Órdenes de Trabajo'!$F$2)+1)/('1. Órdenes de Trabajo'!$F$2:$F$301=$C$4),1),"")
B27: =IFERROR(INDEX('1. Órdenes de Trabajo'!$A$2:$A$301,$T27),"") | C27: =IFERROR(INDEX('1. Órdenes de Trabajo'!$B$2:$B$301,$T27),"") | D27: =IFERROR(INDEX('1. Órdenes de Trabajo'!$D$2:$D$301,$T27),"") | E27: =IFERROR(INDEX('1. Órdenes de Trabajo'!$J$2:$J$301,$T27),"") | F27: =IFERROR(INDEX('1. Órdenes de Trabajo'!$K$2:$K$301,$T27),"") | T27: =IFERROR(_xludf.aggregate(15,6,(ROW('1. Órdenes de Trabajo'!$F$2:$F$301)-ROW('1. Órdenes de Trabajo'!$F$2)+1)/('1. Órdenes de Trabajo'!$F$2:$F$301=$C$4),2),"")
B28: =IFERROR(INDEX('1. Órdenes de Trabajo'!$A$2:$A$301,$T28),"") | C28: =IFERROR(INDEX('1. Órdenes de Trabajo'!$B$2:$B$301,$T28),"") | D28: =IFERROR(INDEX('1. Órdenes de Trabajo'!$D$2:$D$301,$T28),"") | E28: =IFERROR(INDEX('1. Órdenes de Trabajo'!$J$2:$J$301,$T28),"") | F28: =IFERROR(INDEX('1. Órdenes de Trabajo'!$K$2:$K$301,$T28),"") | T28: =IFERROR(_xludf.aggregate(15,6,(ROW('1. Órdenes de Trabajo'!$F$2:$F$301)-ROW('1. Órdenes de Trabajo'!$F$2)+1)/('1. Órdenes de Trabajo'!$F$2:$F$301=$C$4),3),"")
B29: =IFERROR(INDEX('1. Órdenes de Trabajo'!$A$2:$A$301,$T29),"") | C29: =IFERROR(INDEX('1. Órdenes de Trabajo'!$B$2:$B$301,$T29),"") | D29: =IFERROR(INDEX('1. Órdenes de Trabajo'!$D$2:$D$301,$T29),"") | E29: =IFERROR(INDEX('1. Órdenes de Trabajo'!$J$2:$J$301,$T29),"") | F29: =IFERROR(INDEX('1. Órdenes de Trabajo'!$K$2:$K$301,$T29),"") | T29: =IFERROR(_xludf.aggregate(15,6,(ROW('1. Órdenes de Trabajo'!$F$2:$F$301)-ROW('1. Órdenes de Trabajo'!$F$2)+1)/('1. Órdenes de Trabajo'!$F$2:$F$301=$C$4),4),"")
B30: =IFERROR(INDEX('1. Órdenes de Trabajo'!$A$2:$A$301,$T30),"") | C30: =IFERROR(INDEX('1. Órdenes de Trabajo'!$B$2:$B$301,$T30),"") | D30: =IFERROR(INDEX('1. Órdenes de Trabajo'!$D$2:$D$301,$T30),"") | E30: =IFERROR(INDEX('1. Órdenes de Trabajo'!$J$2:$J$301,$T30),"") | F30: =IFERROR(INDEX('1. Órdenes de Trabajo'!$K$2:$K$301,$T30),"") | T30: =IFERROR(_xludf.aggregate(15,6,(ROW('1. Órdenes de Trabajo'!$F$2:$F$301)-ROW('1. Órdenes de Trabajo'!$F$2)+1)/('1. Órdenes de Trabajo'!$F$2:$F$301=$C$4),5),"")
B31: =IFERROR(INDEX('1. Órdenes de Trabajo'!$A$2:$A$301,$T31),"") | C31: =IFERROR(INDEX('1. Órdenes de Trabajo'!$B$2:$B$301,$T31),"") | D31: =IFERROR(INDEX('1. Órdenes de Trabajo'!$D$2:$D$301,$T31),"") | E31: =IFERROR(INDEX('1. Órdenes de Trabajo'!$J$2:$J$301,$T31),"") | F31: =IFERROR(INDEX('1. Órdenes de Trabajo'!$K$2:$K$301,$T31),"") | T31: =IFERROR(_xludf.aggregate(15,6,(ROW('1. Órdenes de Trabajo'!$F$2:$F$301)-ROW('1. Órdenes de Trabajo'!$F$2)+1)/('1. Órdenes de Trabajo'!$F$2:$F$301=$C$4),6),"")
B33: HISTORIAL PREVENTIVO
B34: Mes | C34: Resultado | D34: Fecha | E34: Ingeniero
B35: =IFERROR(INDEX('Registro MP'!$G$2:$G$301,$T35),"") | C35: =IFERROR(INDEX('Registro MP'!$J$2:$J$301,$T35),"") | D35: =IFERROR(INDEX('Registro MP'!$L$2:$L$301,$T35),"") | E35: =IFERROR(INDEX('Registro MP'!$N$2:$N$301,$T35),"") | T35: =IFERROR(_xludf.aggregate(15,6,(ROW('Registro MP'!$A$2:$A$301)-ROW('Registro MP'!$A$2)+1)/('Registro MP'!$A$2:$A$301=$C$4),1),"")
B36: =IFERROR(INDEX('Registro MP'!$G$2:$G$301,$T36),"") | C36: =IFERROR(INDEX('Registro MP'!$J$2:$J$301,$T36),"") | D36: =IFERROR(INDEX('Registro MP'!$L$2:$L$301,$T36),"") | E36: =IFERROR(INDEX('Registro MP'!$N$2:$N$301,$T36),"") | T36: =IFERROR(_xludf.aggregate(15,6,(ROW('Registro MP'!$A$2:$A$301)-ROW('Registro MP'!$A$2)+1)/('Registro MP'!$A$2:$A$301=$C$4),2),"")
B37: =IFERROR(INDEX('Registro MP'!$G$2:$G$301,$T37),"") | C37: =IFERROR(INDEX('Registro MP'!$J$2:$J$301,$T37),"") | D37: =IFERROR(INDEX('Registro MP'!$L$2:$L$301,$T37),"") | E37: =IFERROR(INDEX('Registro MP'!$N$2:$N$301,$T37),"") | T37: =IFERROR(_xludf.aggregate(15,6,(ROW('Registro MP'!$A$2:$A$301)-ROW('Registro MP'!$A$2)+1)/('Registro MP'!$A$2:$A$301=$C$4),3),"")
B38: =IFERROR(INDEX('Registro MP'!$G$2:$G$301,$T38),"") | C38: =IFERROR(INDEX('Registro MP'!$J$2:$J$301,$T38),"") | D38: =IFERROR(INDEX('Registro MP'!$L$2:$L$301,$T38),"") | E38: =IFERROR(INDEX('Registro MP'!$N$2:$N$301,$T38),"") | T38: =IFERROR(_xludf.aggregate(15,6,(ROW('Registro MP'!$A$2:$A$301)-ROW('Registro MP'!$A$2)+1)/('Registro MP'!$A$2:$A$301=$C$4),4),"")
B39: =IFERROR(INDEX('Registro MP'!$G$2:$G$301,$T39),"") | C39: =IFERROR(INDEX('Registro MP'!$J$2:$J$301,$T39),"") | D39: =IFERROR(INDEX('Registro MP'!$L$2:$L$301,$T39),"") | E39: =IFERROR(INDEX('Registro MP'!$N$2:$N$301,$T39),"") | T39: =IFERROR(_xludf.aggregate(15,6,(ROW('Registro MP'!$A$2:$A$301)-ROW('Registro MP'!$A$2)+1)/('Registro MP'!$A$2:$A$301=$C$4),5),"")
B40: =IFERROR(INDEX('Registro MP'!$G$2:$G$301,$T40),"") | C40: =IFERROR(INDEX('Registro MP'!$J$2:$J$301,$T40),"") | D40: =IFERROR(INDEX('Registro MP'!$L$2:$L$301,$T40),"") | E40: =IFERROR(INDEX('Registro MP'!$N$2:$N$301,$T40),"") | T40: =IFERROR(_xludf.aggregate(15,6,(ROW('Registro MP'!$A$2:$A$301)-ROW('Registro MP'!$A$2)+1)/('Registro MP'!$A$2:$A$301=$C$4),6),"")
B41: =IFERROR(INDEX('Registro MP'!$G$2:$G$301,$T41),"") | C41: =IFERROR(INDEX('Registro MP'!$J$2:$J$301,$T41),"") | D41: =IFERROR(INDEX('Registro MP'!$L$2:$L$301,$T41),"") | E41: =IFERROR(INDEX('Registro MP'!$N$2:$N$301,$T41),"") | T41: =IFERROR(_xludf.aggregate(15,6,(ROW('Registro MP'!$A$2:$A$301)-ROW('Registro MP'!$A$2)+1)/('Registro MP'!$A$2:$A$301=$C$4),7),"")
B42: =IFERROR(INDEX('Registro MP'!$G$2:$G$301,$T42),"") | C42: =IFERROR(INDEX('Registro MP'!$J$2:$J$301,$T42),"") | D42: =IFERROR(INDEX('Registro MP'!$L$2:$L$301,$T42),"") | E42: =IFERROR(INDEX('Registro MP'!$N$2:$N$301,$T42),"") | T42: =IFERROR(_xludf.aggregate(15,6,(ROW('Registro MP'!$A$2:$A$301)-ROW('Registro MP'!$A$2)+1)/('Registro MP'!$A$2:$A$301=$C$4),8),"")
B43: =IFERROR(INDEX('Registro MP'!$G$2:$G$301,$T43),"") | C43: =IFERROR(INDEX('Registro MP'!$J$2:$J$301,$T43),"") | D43: =IFERROR(INDEX('Registro MP'!$L$2:$L$301,$T43),"") | E43: =IFERROR(INDEX('Registro MP'!$N$2:$N$301,$T43),"") | T43: =IFERROR(_xludf.aggregate(15,6,(ROW('Registro MP'!$A$2:$A$301)-ROW('Registro MP'!$A$2)+1)/('Registro MP'!$A$2:$A$301=$C$4),9),"")
B44: =IFERROR(INDEX('Registro MP'!$G$2:$G$301,$T44),"") | C44: =IFERROR(INDEX('Registro MP'!$J$2:$J$301,$T44),"") | D44: =IFERROR(INDEX('Registro MP'!$L$2:$L$301,$T44),"") | E44: =IFERROR(INDEX('Registro MP'!$N$2:$N$301,$T44),"") | T44: =IFERROR(_xludf.aggregate(15,6,(ROW('Registro MP'!$A$2:$A$301)-ROW('Registro MP'!$A$2)+1)/('Registro MP'!$A$2:$A$301=$C$4),10),"")
B46: PENDIENTES DEL EQUIPO
B47: Tipo | C47: Estado | D47: Vence | E47: Responsable | F47: Descripción
...

Sheet Tablero
A1: Tablero
A2: Operatividad correctiva en tiempo real y avance del programa preventivo 2026 · se actualiza solo al cargar datos
A3: Hoy: | B3: =TODAY() -> 46191
A5: Casos abiertos | B5: Equipos No Operativos | C5: En Servicio Técnico | D5: Dados de baja | E5: Casos cerrados | F5: Pendientes documentales
A6: =COUNTIF('1. Órdenes de Trabajo'!$J$2:$J$301,"Abierto") -> 11 | B6: =COUNTIFS('1. Órdenes de Trabajo'!$J$2:$J$301,"Abierto",'1. Órdenes de Trabajo'!$H$2:$H$301,"No Operativo") -> 11 | C6: =SUMPRODUCT(('5. Servicio Técnico (Envíos)'!$A$2:$A$301<>"")*('5. Servicio Técnico (Envíos)'!$I$2:$I$301="")) -> 8 | D6: =COUNTIF('6. Bajas'!$A$2:$A$301,"?*") -> 0 | E6: =COUNTIF('1. Órdenes de Trabajo'!$J$2:$J$301,"Cerrado") -> 4 | F6: =COUNTIF('4. Visitas Técnicas'!$L$2:$L$301,"No")+COUNTIF('5. Servicio Técnico (Envíos)'!$M$2:$M$301,"No") -> 2
A9: Folio SIGEM | B9: Equipo | C9: Servicio | D9: Estado actual | E9: Técnico asignado | F9: Fecha OT | G9: Días abierto | H9: Evento
A10: =IF('1. Órdenes de Trabajo'!$J2="Abierto",'1. Órdenes de Trabajo'!$A2,"") | B10: =IF('1. Órdenes de Trabajo'!$J2="Abierto",'1. Órdenes de Trabajo'!$E2,"") | C10: =IF('1. Órdenes de Trabajo'!$J2="Abierto",'1. Órdenes de Trabajo'!$I2,"") | D10: =IF('1. Órdenes de Trabajo'!$J2="Abierto",IF(COUNTIF('6. Bajas'!$A$2:$A$301,'1. Órdenes de Trabajo'!$A2)>0,"Baja",IF(SUMPRODUCT(('5. Servicio Técnico (Envíos)'!$A$2:$A$301='1. Órdenes de Trabajo'!$A2)*('5. Servicio Técnico (Envíos)'!$I$2:$I$301=""))>0,"Servicio Técnico",'1. Órdenes de Trabajo'!$H2)),"") | E10: =IF('1. Órdenes de Trabajo'!$J2="Abierto",'1. Órdenes de Trabajo'!$C2,"") | F10: =IF('1. Órdenes de Trabajo'!$J2="Abierto",'1. Órdenes de Trabajo'!$B2,"") | G10: =IFERROR(IF('1. Órdenes de Trabajo'!$J2="Abierto",IF('1. Órdenes de Trabajo'!$B2="","",TODAY()-IF(ISNUMBER('1. Órdenes de Trabajo'!$B2),'1. Órdenes de Trabajo'!$B2,DATE(VALUE(MID('1. Órdenes de Trabajo'!$B2,7,4)),VALUE(MID('1. Órdenes de Trabajo'!$B2,4,2)),VALUE(MID('1. Órdenes de Trabajo'!$B2,1,2))))),""),"") | H10: =IF('1. Órdenes de Trabajo'!$J2="Abierto",'1. Órdenes de Trabajo'!$J2,"")
A11: =IF('1. Órdenes de Trabajo'!$J3="Abierto",'1. Órdenes de Trabajo'!$A3,"") -> 2025-121109-19-18809 | B11: =IF('1. Órdenes de Trabajo'!$J3="Abierto",'1. Órdenes de Trabajo'!$E3,"") -> Ventilador Mecánico | C11: =IF('1. Órdenes de Trabajo'!$J3="Abierto",'1. Órdenes de Trabajo'!$I3,"") -> UPC Pediátrica | D11: =IF('1. Órdenes de Trabajo'!$J3="Abierto",IF(COUNTIF('6. Bajas'!$A$2:$A$301,'1. Órdenes de Trabajo'!$A3)>0,"Baja",IF(SUMPRODUCT(('5. Servicio Técnico (Envíos)'!$A$2:$A$301='1. Órdenes de Trabajo'!$A3)*('5. Servicio Técnico (Envíos)'!$I$2:$I$301=""))>0,"Servicio Técnico",'1. Órdenes de Trabajo'!$H3)),"") -> No Operativo | E11: =IF('1. Órdenes de Trabajo'!$J3="Abierto",'1. Órdenes de Trabajo'!$C3,"") -> Ricardo Matus Aroca | F11: =IF('1. Órdenes de Trabajo'!$J3="Abierto",'1. Órdenes de Trabajo'!$B3,"") -> 24-10-2025 | G11: =IFERROR(IF('1. Órdenes de Trabajo'!$J3="Abierto",IF('1. Órdenes de Trabajo'!$B3="","",TODAY()-IF(ISNUMBER('1. Órdenes de Trabajo'!$B3),'1. Órdenes de Trabajo'!$B3,DATE(VALUE(MID('1. Órdenes de Trabajo'!$B3,7,4)),VALUE(MID('1. Órdenes de Trabajo'!$B3,4,2)),VALUE(MID('1. Órdenes de Trabajo'!$B3,1,2))))),""),"") -> 237 | H11: =IF('1. Órdenes de Trabajo'!$J3="Abierto",'1. Órdenes de Trabajo'!$J3,"") -> Abierto
A12: =IF('1. Órdenes de Trabajo'!$J4="Abierto",'1. Órdenes de Trabajo'!$A4,"") | B12: =IF('1. Órdenes de Trabajo'!$J4="Abierto",'1. Órdenes de Trabajo'!$E4,"") | C12: =IF('1. Órdenes de Trabajo'!$J4="Abierto",'1. Órdenes de Trabajo'!$I4,"") | D12: =IF('1. Órdenes de Trabajo'!$J4="Abierto",IF(COUNTIF('6. Bajas'!$A$2:$A$301,'1. Órdenes de Trabajo'!$A4)>0,"Baja",IF(SUMPRODUCT(('5. Servicio Técnico (Envíos)'!$A$2:$A$301='1. Órdenes de Trabajo'!$A4)*('5. Servicio Técnico (Envíos)'!$I$2:$I$301=""))>0,"Servicio Técnico",'1. Órdenes de Trabajo'!$H4)),"") | E12: =IF('1. Órdenes de Trabajo'!$J4="Abierto",'1. Órdenes de Trabajo'!$C4,"") | F12: =IF('1. Órdenes de Trabajo'!$J4="Abierto",'1. Órdenes de Trabajo'!$B4,"") | G12: =IFERROR(IF('1. Órdenes de Trabajo'!$J4="Abierto",IF('1. Órdenes de Trabajo'!$B4="","",TODAY()-IF(ISNUMBER('1. Órdenes de Trabajo'!$B4),'1. Órdenes de Trabajo'!$B4,DATE(VALUE(MID('1. Órdenes de Trabajo'!$B4,7,4)),VALUE(MID('1. Órdenes de Trabajo'!$B4,4,2)),VALUE(MID('1. Órdenes de Trabajo'!$B4,1,2))))),""),"") | H12: =IF('1. Órdenes de Trabajo'!$J4="Abierto",'1. Órdenes de Trabajo'!$J4,"")
A13: =IF('1. Órdenes de Trabajo'!$J5="Abierto",'1. Órdenes de Trabajo'!$A5,"") | B13: =IF('1. Órdenes de Trabajo'!$J5="Abierto",'1. Órdenes de Trabajo'!$E5,"") | C13: =IF('1. Órdenes de Trabajo'!$J5="Abierto",'1. Órdenes de Trabajo'!$I5,"") | D13: =IF('1. Órdenes de Trabajo'!$J5="Abierto",IF(COUNTIF('6. Bajas'!$A$2:$A$301,'1. Órdenes de Trabajo'!$A5)>0,"Baja",IF(SUMPRODUCT(('5. Servicio Técnico (Envíos)'!$A$2:$A$301='1. Órdenes de Trabajo'!$A5)*('5. Servicio Técnico (Envíos)'!$I$2:$I$301=""))>0,"Servicio Técnico",'1. Órdenes de Trabajo'!$H5)),"") | E13: =IF('1. Órdenes de Trabajo'!$J5="Abierto",'1. Órdenes de Trabajo'!$C5,"") | F13: =IF('1. Órdenes de Trabajo'!$J5="Abierto",'1. Órdenes de Trabajo'!$B5,"") | G13: =IFERROR(IF('1. Órdenes de Trabajo'!$J5="Abierto",IF('1. Órdenes de Trabajo'!$B5="","",TODAY()-IF(ISNUMBER('1. Órdenes de Trabajo'!$B5),'1. Órdenes de Trabajo'!$B5,DATE(VALUE(MID('1. Órdenes de Trabajo'!$B5,7,4)),VALUE(MID('1. Órdenes de Trabajo'!$B5,4,2)),VALUE(MID('1. Órdenes de Trabajo'!$B5,1,2))))),""),"") | H13: =IF('1. Órdenes de Trabajo'!$J5="Abierto",'1. Órdenes de Trabajo'!$J5,"")
A14: =IF('1. Órdenes de Trabajo'!$J6="Abierto",'1. Órdenes de Trabajo'!$A6,"") -> 2026-121109-19-6215 | B14: =IF('1. Órdenes de Trabajo'!$J6="Abierto",'1. Órdenes de Trabajo'!$E6,"") -> Máquina Diálisis | C14: =IF('1. Órdenes de Trabajo'!$J6="Abierto",'1. Órdenes de Trabajo'!$I6,"") -> Hemodiálisis | D14: =IF('1. Órdenes de Trabajo'!$J6="Abierto",IF(COUNTIF('6. Bajas'!$A$2:$A$301,'1. Órdenes de Trabajo'!$A6)>0,"Baja",IF(SUMPRODUCT(('5. Servicio Técnico (Envíos)'!$A$2:$A$301='1. Órdenes de Trabajo'!$A6)*('5. Servicio Técnico (Envíos)'!$I$2:$I$301=""))>0,"Servicio Técnico",'1. Órdenes de Trabajo'!$H6)),"") -> No Operativo | E14: =IF('1. Órdenes de Trabajo'!$J6="Abierto",'1. Órdenes de Trabajo'!$C6,"") -> Cristián Beltrán Oviedo | F14: =IF('1. Órdenes de Trabajo'!$J6="Abierto",'1. Órdenes de Trabajo'!$B6,"") -> 06-04-2026 | G14: =IFERROR(IF('1. Órdenes de Trabajo'!$J6="Abierto",IF('1. Órdenes de Trabajo'!$B6="","",TODAY()-IF(ISNUMBER('1. Órdenes de Trabajo'!$B6),'1. Órdenes de Trabajo'!$B6,DATE(VALUE(MID('1. Órdenes de Trabajo'!$B6,7,4)),VALUE(MID('1. Órdenes de Trabajo'!$B6,4,2)),VALUE(MID('1. Órdenes de Trabajo'!$B6,1,2))))),""),"") -> 73 | H14: =IF('1. Órdenes de Trabajo'!$J6="Abierto",'1. Órdenes de Trabajo'!$J6,"") -> Abierto
A15: =IF('1. Órdenes de Trabajo'!$J7="Abierto",'1. Órdenes de Trabajo'!$A7,"") -> 2026-121109-19-6271 | B15: =IF('1. Órdenes de Trabajo'!$J7="Abierto",'1. Órdenes de Trabajo'!$E7,"") -> Ventilador Mecánico | C15: =IF('1. Órdenes de Trabajo'!$J7="Abierto",'1. Órdenes de Trabajo'!$I7,"") -> UPC 3er Piso | D15: =IF('1. Órdenes de Trabajo'!$J7="Abierto",IF(COUNTIF('6. Bajas'!$A$2:$A$301,'1. Órdenes de Trabajo'!$A7)>0,"Baja",IF(SUMPRODUCT(('5. Servicio Técnico (Envíos)'!$A$2:$A$301='1. Órdenes de Trabajo'!$A7)*('5. Servicio Técnico (Envíos)'!$I$2:$I$301=""))>0,"Servicio Técnico",'1. Órdenes de Trabajo'!$H7)),"") -> Servicio Técnico | E15: =IF('1. Órdenes de Trabajo'!$J7="Abierto",'1. Órdenes de Trabajo'!$C7,"") -> Ricardo Matus Aroca | F15: =IF('1. Órdenes de Trabajo'!$J7="Abierto",'1. Órdenes de Trabajo'!$B7,"") -> 07-04-2026 | G15: =IFERROR(IF('1. Órdenes de Trabajo'!$J7="Abierto",IF('1. Órdenes de Trabajo'!$B7="","",TODAY()-IF(ISNUMBER('1. Órdenes de Trabajo'!$B7),'1. Órdenes de Trabajo'!$B7,DATE(VALUE(MID('1. Órdenes de Trabajo'!$B7,7,4)),VALUE(MID('1. Órdenes de Trabajo'!$B7,4,2)),VALUE(MID('1. Órdenes de Trabajo'!$B7,1,2))))),""),"") -> 72 | H15: =IF('1. Órdenes de Trabajo'!$J7="Abierto",'1. Órdenes de Trabajo'!$J7,"") -> Abierto
A16: =IF('1. Órdenes de Trabajo'!$J8="Abierto",'1. Órdenes de Trabajo'!$A8,"") -> 2026-121109-19-6374 | B16: =IF('1. Órdenes de Trabajo'!$J8="Abierto",'1. Órdenes de Trabajo'!$E8,"") -> Ventilador Mecánico | C16: =IF('1. Órdenes de Trabajo'!$J8="Abierto",'1. Órdenes de Trabajo'!$I8,"") -> UPC 3er Piso | D16: =IF('1. Órdenes de Trabajo'!$J8="Abierto",IF(COUNTIF('6. Bajas'!$A$2:$A$301,'1. Órdenes de Trabajo'!$A8)>0,"Baja",IF(SUMPRODUCT(('5. Servicio Técnico (Envíos)'!$A$2:$A$301='1. Órdenes de Trabajo'!$A8)*('5. Servicio Técnico (Envíos)'!$I$2:$I$301=""))>0,"Servicio Técnico",'1. Órdenes de Trabajo'!$H8)),"") -> Servicio Técnico | E16: =IF('1. Órdenes de Trabajo'!$J8="Abierto",'1. Órdenes de Trabajo'!$C8,"") -> Ricardo Matus Aroca | F16: =IF('1. Órdenes de Trabajo'!$J8="Abierto",'1. Órdenes de Trabajo'!$B8,"") -> 08-04-2026 | G16: =IFERROR(IF('1. Órdenes de Trabajo'!$J8="Abierto",IF('1. Órdenes de Trabajo'!$B8="","",TODAY()-IF(ISNUMBER('1. Órdenes de Trabajo'!$B8),'1. Órdenes de Trabajo'!$B8,DATE(VALUE(MID('1. Órdenes de Trabajo'!$B8,7,4)),VALUE(MID('1. Órdenes de Trabajo'!$B8,4,2)),VALUE(MID('1. Órdenes de Trabajo'!$B8,1,2))))),""),"") -> 71 | H16: =IF('1. Órdenes de Trabajo'!$J8="Abierto",'1. Órdenes de Trabajo'!$J8,"") -> Abierto
A17: =IF('1. Órdenes de Trabajo'!$J9="Abierto",'1. Órdenes de Trabajo'!$A9,"") | B17: =IF('1. Órdenes de Trabajo'!$J9="Abierto",'1. Órdenes de Trabajo'!$E9,"") | C17: =IF('1. Órdenes de Trabajo'!$J9="Abierto",'1. Órdenes de Trabajo'!$I9,"") | D17: =IF('1. Órdenes de Trabajo'!$J9="Abierto",IF(COUNTIF('6. Bajas'!$A$2:$A$301,'1. Órdenes de Trabajo'!$A9)>0,"Baja",IF(SUMPRODUCT(('5. Servicio Técnico (Envíos)'!$A$2:$A$301='1. Órdenes de Trabajo'!$A9)*('5. Servicio Técnico (Envíos)'!$I$2:$I$301=""))>0,"Servicio Técnico",'1. Órdenes de Trabajo'!$H9)),"") | E17: =IF('1. Órdenes de Trabajo'!$J9="Abierto",'1. Órdenes de Trabajo'!$C9,"") | F17: =IF('1. Órdenes de Trabajo'!$J9="Abierto",'1. Órdenes de Trabajo'!$B9,"") | G17: =IFERROR(IF('1. Órdenes de Trabajo'!$J9="Abierto",IF('1. Órdenes de Trabajo'!$B9="","",TODAY()-IF(ISNUMBER('1. Órdenes de Trabajo'!$B9),'1. Órdenes de Trabajo'!$B9,DATE(VALUE(MID('1. Órdenes de Trabajo'!$B9,7,4)),VALUE(MID('1. Órdenes de Trabajo'!$B9,4,2)),VALUE(MID('1. Órdenes de Trabajo'!$B9,1,2))))),""),"") | H17: =IF('1. Órdenes de Trabajo'!$J9="Abierto",'1. Órdenes de Trabajo'!$J9,"")
A18: =IF('1. Órdenes de Trabajo'!$J10="Abierto",'1. Órdenes de Trabajo'!$A10,"") -> 2026-121109-19-7762 | B18: =IF('1. Órdenes de Trabajo'!$J10="Abierto",'1. Órdenes de Trabajo'!$E10,"") -> Monitor Multiparámetros | C18: =IF('1. Órdenes de Trabajo'!$J10="Abierto",'1. Órdenes de Trabajo'!$I10,"") -> Medicina | D18: =IF('1. Órdenes de Trabajo'!$J10="Abierto",IF(COUNTIF('6. Bajas'!$A$2:$A$301,'1. Órdenes de Trabajo'!$A10)>0,"Baja",IF(SUMPRODUCT(('5. Servicio Técnico (Envíos)'!$A$2:$A$301='1. Órdenes de Trabajo'!$A10)*('5. Servicio Técnico (Envíos)'!$I$2:$I$301=""))>0,"Servicio Técnico",'1. Órdenes de Trabajo'!$H10)),"") -> Servicio Técnico | E18: =IF('1. Órdenes de Trabajo'!$J10="Abierto",'1. Órdenes de Trabajo'!$C10,"") -> Carlos Bahamondes Seguel | F18: =IF('1. Órdenes de Trabajo'!$J10="Abierto",'1. Órdenes de Trabajo'!$B10,"") -> 27-04-2026 | G18: =IFERROR(IF('1. Órdenes de Trabajo'!$J10="Abierto",IF('1. Órdenes de Trabajo'!$B10="","",TODAY()-IF(ISNUMBER('1. Órdenes de Trabajo'!$B10),'1. Órdenes de Trabajo'!$B10,DATE(VALUE(MID('1. Órdenes de Trabajo'!$B10,7,4)),VALUE(MID('1. Órdenes de Trabajo'!$B10,4,2)),VALUE(MID('1. Órdenes de Trabajo'!$B10,1,2))))),""),"") -> 52 | H18: =IF('1. Órdenes de Trabajo'!$J10="Abierto",'1. Órdenes de Trabajo'!$J10,"") -> Abierto
A19: =IF('1. Órdenes de Trabajo'!$J11="Abierto",'1. Órdenes de Trabajo'!$A11,"") -> 2026-121109-19-9046 | B19: =IF('1. Órdenes de Trabajo'!$J11="Abierto",'1. Órdenes de Trabajo'!$E11,"") -> Monitor Multiparámetros | C19: =IF('1. Órdenes de Trabajo'!$J11="Abierto",'1. Órdenes de Trabajo'!$I11,"") -> Medicina | D19: =IF('1. Órdenes de Trabajo'!$J11="Abierto",IF(COUNTIF('6. Bajas'!$A$2:$A$301,'1. Órdenes de Trabajo'!$A11)>0,"Baja",IF(SUMPRODUCT(('5. Servicio Técnico (Envíos)'!$A$2:$A$301='1. Órdenes de Trabajo'!$A11)*('5. Servicio Técnico (Envíos)'!$I$2:$I$301=""))>0,"Servicio Técnico",'1. Órdenes de Trabajo'!$H11)),"") -> Servicio Técnico | E19: =IF('1. Órdenes de Trabajo'!$J11="Abierto",'1. Órdenes de Trabajo'!$C11,"") -> Carlos Bahamondes Seguel | F19: =IF('1. Órdenes de Trabajo'!$J11="Abierto",'1. Órdenes de Trabajo'!$B11,"") -> 14-05-2026 | G19: =IFERROR(IF('1. Órdenes de Trabajo'!$J11="Abierto",IF('1. Órdenes de Trabajo'!$B11="","",TODAY()-IF(ISNUMBER('1. Órdenes de Trabajo'!$B11),'1. Órdenes de Trabajo'!$B11,DATE(VALUE(MID('1. Órdenes de Trabajo'!$B11,7,4)),VALUE(MID('1. Órdenes de Trabajo'!$B11,4,2)),VALUE(MID('1. Órdenes de Trabajo'!$B11,1,2))))),""),"") -> 35 | H19: =IF('1. Órdenes de Trabajo'!$J11="Abierto",'1. Órdenes de Trabajo'!$J11,"") -> Abierto
A20: =IF('1. Órdenes de Trabajo'!$J12="Abierto",'1. Órdenes de Trabajo'!$A12,"") -> 2026-121109-19-9887 | B20: =IF('1. Órdenes de Trabajo'!$J12="Abierto",'1. Órdenes de Trabajo'!$E12,"") -> Monitor Multiparámetros | C20: =IF('1. Órdenes de Trabajo'!$J12="Abierto",'1. Órdenes de Trabajo'!$I12,"") -> Pabellones Gineco-Obstétricos | D20: =IF('1. Órdenes de Trabajo'!$J12="Abierto",IF(COUNTIF('6. Bajas'!$A$2:$A$301,'1. Órdenes de Trabajo'!$A12)>0,"Baja",IF(SUMPRODUCT(('5. Servicio Técnico (Envíos)'!$A$2:$A$301='1. Órdenes de Trabajo'!$A12)*('5. Servicio Técnico (Envíos)'!$I$2:$I$301=""))>0,"Servicio Técnico",'1. Órdenes de Trabajo'!$H12)),"") -> Servicio Técnico | E20: =IF('1. Órdenes de Trabajo'!$J12="Abierto",'1. Órdenes de Trabajo'!$C12,"") -> Cristina Rozas Urrutia | F20: =IF('1. Órdenes de Trabajo'!$J12="Abierto",'1. Órdenes de Trabajo'!$B12,"") -> 28-05-2026 | G20: =IFERROR(IF('1. Órdenes de Trabajo'!$J12="Abierto",IF('1. Órdenes de Trabajo'!$B12="","",TODAY()-IF(ISNUMBER('1. Órdenes de Trabajo'!$B12),'1. Órdenes de Trabajo'!$B12,DATE(VALUE(MID('1. Órdenes de Trabajo'!$B12,7,4)),VALUE(MID('1. Órdenes de Trabajo'!$B12,4,2)),VALUE(MID('1. Órdenes de Trabajo'!$B12,1,2))))),""),"") -> 21 | H20: =IF('1. Órdenes de Trabajo'!$J12="Abierto",'1. Órdenes de Trabajo'!$J12,"") -> Abierto
A21: =IF('1. Órdenes de Trabajo'!$J13="Abierto",'1. Órdenes de Trabajo'!$A13,"") -> 2026-121109-19-10081 | B21: =IF('1. Órdenes de Trabajo'!$J13="Abierto",'1. Órdenes de Trabajo'!$E13,"") -> Máquina Diálisis | C21: =IF('1. Órdenes de Trabajo'!$J13="Abierto",'1. Órdenes de Trabajo'!$I13,"") -> UPC Adulto | D21: =IF('1. Órdenes de Trabajo'!$J13="Abierto",IF(COUNTIF('6. Bajas'!$A$2:$A$301,'1. Órdenes de Trabajo'!$A13)>0,"Baja",IF(SUMPRODUCT(('5. Servicio Técnico (Envíos)'!$A$2:$A$301='1. Órdenes de Trabajo'!$A13)*('5. Servicio Técnico (Envíos)'!$I$2:$I$301=""))>0,"Servicio Técnico",'1. Órdenes de Trabajo'!$H13)),"") -> No Operativo | E21: =IF('1. Órdenes de Trabajo'!$J13="Abierto",'1. Órdenes de Trabajo'!$C13,"") -> Cristián Beltrán Oviedo | F21: =IF('1. Órdenes de Trabajo'!$J13="Abierto",'1. Órdenes de Trabajo'!$B13,"") -> 01-06-2026 | G21: =IFERROR(IF('1. Órdenes de Trabajo'!$J13="Abierto",IF('1. Órdenes de Trabajo'!$B13="","",TODAY()-IF(ISNUMBER('1. Órdenes de Trabajo'!$B13),'1. Órdenes de Trabajo'!$B13,DATE(VALUE(MID('1. Órdenes de Trabajo'!$B13,7,4)),VALUE(MID('1. Órdenes de Trabajo'!$B13,4,2)),VALUE(MID('1. Órdenes de Trabajo'!$B13,1,2))))),""),"") -> 17 | H21: =IF('1. Órdenes de Trabajo'!$J13="Abierto",'1. Órdenes de Trabajo'!$J13,"") -> Abierto
... A89: =IF('1. Órdenes de Trabajo'!$J81="Abierto",'1. Órdenes de Trabajo'!$A81,"") | B89: =IF('1. Órdenes de Trabajo'!$J81="Abierto",'1. Órdenes de Trabajo'!$E81,"") | C89: =IF('1. Órdenes de Trabajo'!$J81="Abierto",'1. Órdenes de Trabajo'!$I81,"") | D89: =IF('1. Órdenes de Trabajo'!$J81="Abierto",IF(COUNTIF('6. Bajas'!$A$2:$A$301,'1. Órdenes de Trabajo'!$A81)>0,"Baja",IF(SUMPRODUCT(('5. Servicio Técnico (Envíos)'!$A$2:$A$301='1. Órdenes de Trabajo'!$A81)*('5. Servicio Técnico (Envíos)'!$I$2:$I$301=""))>0,"Servicio Técnico",'1. Órdenes de Trabajo'!$H81)),"") | E89: =IF('1. Órdenes de Trabajo'!$J81="Abierto",'1. Órdenes de Trabajo'!$C81,"") | F89: =IF('1. Órdenes de Trabajo'!$J81="Abierto",'1. Órdenes de Trabajo'!$B81,"") | G89: =IFERROR(IF('1. Órdenes de Trabajo'!$J81="Abierto",IF('1. Órdenes de Trabajo'!$B81="","",TODAY()-IF(ISNUMBER('1. Órdenes de Trabajo'!$B81),'1. Órdenes de Trabajo'!$B81,DATE(VALUE(MID('1. Órdenes de Trabajo'!$B81,7,4)),VALUE(MID('1. Órdenes de Trabajo'!$B81,4,2)),VALUE(MID('1. Órdenes de Trabajo'!$B81,1,2))))),""),"") | H89: =IF('1. Órdenes de Trabajo'!$J81="Abierto",'1. Órdenes de Trabajo'!$J81,"")
A91: Nota: el «Estado actual» se calcula así — si el equipo está en Bajas muestra «Baja»; si tiene un envío a servicio técnico sin retorno registrado muestra «Servicio Técnico»; en otro caso, el estado inicial de la OT. Solo se listan casos con evento «Abierto». Los días en rojo superan los 30.
A93: Pendientes documentales (equipo retornado/atendido, falta Reporte de Servicio)
A94: Incluye casos aunque la OT esté cerrada: el equipo opera, pero falta el respaldo documental para la carpeta física.
A95: Folio SIGEM | B95: Equipo | C95: Origen | D95: Empresa | E95: Resp. conseguir reporte | F95: Resp. administrativo | G95: Estado OT
A96: =IF('5. Servicio Técnico (Envíos)'!$M2="No",'5. Servicio Técnico (Envíos)'!$A2,"") -> 2025-121109-19-10024 | B96: =IF('5. Servicio Técnico (Envíos)'!$M2="No",IFERROR(VLOOKUP('5. Servicio Técnico (Envíos)'!$A2,'1. Órdenes de Trabajo'!$A$2:$E$301,5,FALSE()),""),"") -> Ventilador Mecánico | C96: =IF('5. Servicio Técnico (Envíos)'!$M2="No","Servicio técnico","") -> Servicio técnico | D96: =IF('5. Servicio Técnico (Envíos)'!$M2="No",'5. Servicio Técnico (Envíos)'!$E2,"") -> DRAGER CHILE LIMITADA | E96: =IF('5. Servicio Técnico (Envíos)'!$M2="No",'5. Servicio Técnico (Envíos)'!$N2,"") -> Ricardo Matus Aroca | F96: =IF('5. Servicio Técnico (Envíos)'!$M2="No",'5. Servicio Técnico (Envíos)'!$O2,"") -> Cristián Beltrán Oviedo | G96: =IF('5. Servicio Técnico (Envíos)'!$M2="No",IFERROR(VLOOKUP('5. Servicio Técnico (Envíos)'!$A2,'1. Órdenes de Trabajo'!$A$2:$J$301,10,FALSE()),""),"") -> Cerrado
A97: =IF('5. Servicio Técnico (Envíos)'!$M3="No",'5. Servicio Técnico (Envíos)'!$A3,"") | B97: =IF('5. Servicio Técnico (Envíos)'!$M3="No",IFERROR(VLOOKUP('5. Servicio Técnico (Envíos)'!$A3,'1. Órdenes de Trabajo'!$A$2:$E$301,5,FALSE()),""),"") | C97: =IF('5. Servicio Técnico (Envíos)'!$M3="No","Servicio técnico","") | D97: =IF('5. Servicio Técnico (Envíos)'!$M3="No",'5. Servicio Técnico (Envíos)'!$E3,"") | E97: =IF('5. Servicio Técnico (Envíos)'!$M3="No",'5. Servicio Técnico (Envíos)'!$N3,"") | F97: =IF('5. Servicio Técnico (Envíos)'!$M3="No",'5. Servicio Técnico (Envíos)'!$O3,"") | G97: =IF('5. Servicio Técnico (Envíos)'!$M3="No",IFERROR(VLOOKUP('5. Servicio Técnico (Envíos)'!$A3,'1. Órdenes de Trabajo'!$A$2:$J$301,10,FALSE()),""),"")
A98: =IF('5. Servicio Técnico (Envíos)'!$M4="No",'5. Servicio Técnico (Envíos)'!$A4,"") | B98: =IF('5. Servicio Técnico (Envíos)'!$M4="No",IFERROR(VLOOKUP('5. Servicio Técnico (Envíos)'!$A4,'1. Órdenes de Trabajo'!$A$2:$E$301,5,FALSE()),""),"") | C98: =IF('5. Servicio Técnico (Envíos)'!$M4="No","Servicio técnico","") | D98: =IF('5. Servicio Técnico (Envíos)'!$M4="No",'5. Servicio Técnico (Envíos)'!$E4,"") | E98: =IF('5. Servicio Técnico (Envíos)'!$M4="No",'5. Servicio Técnico (Envíos)'!$N4,"") | F98: =IF('5. Servicio Técnico (Envíos)'!$M4="No",'5. Servicio Técnico (Envíos)'!$O4,"") | G98: =IF('5. Servicio Técnico (Envíos)'!$M4="No",IFERROR(VLOOKUP('5. Servicio Técnico (Envíos)'!$A4,'1. Órdenes de Trabajo'!$A$2:$J$301,10,FALSE()),""),"")
A99: =IF('5. Servicio Técnico (Envíos)'!$M5="No",'5. Servicio Técnico (Envíos)'!$A5,"") | B99: =IF('5. Servicio Técnico (Envíos)'!$M5="No",IFERROR(VLOOKUP('5. Servicio Técnico (Envíos)'!$A5,'1. Órdenes de Trabajo'!$A$2:$E$301,5,FALSE()),""),"") | C99: =IF('5. Servicio Técnico (Envíos)'!$M5="No","Servicio técnico","") | D99: =IF('5. Servicio Técnico (Envíos)'!$M5="No",'5. Servicio Técnico (Envíos)'!$E5,"") | E99: =IF('5. Servicio Técnico (Envíos)'!$M5="No",'5. Servicio Técnico (Envíos)'!$N5,"") | F99: =IF('5. Servicio Técnico (Envíos)'!$M5="No",'5. Servicio Técnico (Envíos)'!$O5,"") | G99: =IF('5. Servicio Técnico (Envíos)'!$M5="No",IFERROR(VLOOKUP('5. Servicio Técnico (Envíos)'!$A5,'1. Órdenes de Trabajo'!$A$2:$J$301,10,FALSE()),""),"")
A100: =IF('5. Servicio Técnico (Envíos)'!$M6="No",'5. Servicio Técnico (Envíos)'!$A6,"") | B100: =IF('5. Servicio Técnico (Envíos)'!$M6="No",IFERROR(VLOOKUP('5. Servicio Técnico (Envíos)'!$A6,'1. Órdenes de Trabajo'!$A$2:$E$301,5,FALSE()),""),"") | C100: =IF('5. Servicio Técnico (Envíos)'!$M6="No","Servicio técnico","") | D100: =IF('5. Servicio Técnico (Envíos)'!$M6="No",'5. Servicio Técnico (Envíos)'!$E6,"") | E100: =IF('5. Servicio Técnico (Envíos)'!$M6="No",'5. Servicio Técnico (Envíos)'!$N6,"") | F100: =IF('5. Servicio Técnico (Envíos)'!$M6="No",'5. Servicio Técnico (Envíos)'!$O6,"") | G100: =IF('5. Servicio Técnico (Envíos)'!$M6="No",IFERROR(VLOOKUP('5. Servicio Técnico (Envíos)'!$A6,'1. Órdenes de Trabajo'!$A$2:$J$301,10,FALSE()),""),"")
A101: =IF('5. Servicio Técnico (Envíos)'!$M7="No",'5. Servicio Técnico (Envíos)'!$A7,"") | B101: =IF('5. Servicio Técnico (Envíos)'!$M7="No",IFERROR(VLOOKUP('5. Servicio Técnico (Envíos)'!$A7,'1. Órdenes de Trabajo'!$A$2:$E$301,5,FALSE()),""),"") | C101: =IF('5. Servicio Técnico (Envíos)'!$M7="No","Servicio técnico","") | D101: =IF('5. Servicio Técnico (Envíos)'!$M7="No",'5. Servicio Técnico (Envíos)'!$E7,"") | E101: =IF('5. Servicio Técnico (Envíos)'!$M7="No",'5. Servicio Técnico (Envíos)'!$N7,"") | F101: =IF('5. Servicio Técnico (Envíos)'!$M7="No",'5. Servicio Técnico (Envíos)'!$O7,"") | G101: =IF('5. Servicio Técnico (Envíos)'!$M7="No",IFERROR(VLOOKUP('5. Servicio Técnico (Envíos)'!$A7,'1. Órdenes de Trabajo'!$A$2:$J$301,10,FALSE()),""),"")
A102: =IF('5. Servicio Técnico (Envíos)'!$M8="No",'5. Servicio Técnico (Envíos)'!$A8,"") | B102: =IF('5. Servicio Técnico (Envíos)'!$M8="No",IFERROR(VLOOKUP('5. Servicio Técnico (Envíos)'!$A8,'1. Órdenes de Trabajo'!$A$2:$E$301,5,FALSE()),""),"") | C102: =IF('5. Servicio Técnico (Envíos)'!$M8="No","Servicio técnico","") | D102: =IF('5. Servicio Técnico (Envíos)'!$M8="No",'5. Servicio Técnico (Envíos)'!$E8,"") | E102: =IF('5. Servicio Técnico (Envíos)'!$M8="No",'5. Servicio Técnico (Envíos)'!$N8,"") | F102: =IF('5. Servicio Técnico (Envíos)'!$M8="No",'5. Servicio Técnico (Envíos)'!$O8,"") | G102: =IF('5. Servicio Técnico (Envíos)'!$M8="No",IFERROR(VLOOKUP('5. Servicio Técnico (Envíos)'!$A8,'1. Órdenes de Trabajo'!$A$2:$J$301,10,FALSE()),""),"")
A103: =IF('5. Servicio Técnico (Envíos)'!$M9="No",'5. Servicio Técnico (Envíos)'!$A9,"") | B103: =IF('5. Servicio Técnico (Envíos)'!$M9="No",IFERROR(VLOOKUP('5. Servicio Técnico (Envíos)'!$A9,'1. Órdenes de Trabajo'!$A$2:$E$301,5,FALSE()),""),"") | C103: =IF('5. Servicio Técnico (Envíos)'!$M9="No","Servicio técnico","") | D103: =IF('5. Servicio Técnico (Envíos)'!$M9="No",'5. Servicio Técnico (Envíos)'!$E9,"") | E103: =IF('5. Servicio Técnico (Envíos)'!$M9="No",'5. Servicio Técnico (Envíos)'!$N9,"") | F103: =IF('5. Servicio Técnico (Envíos)'!$M9="No",'5. Servicio Técnico (Envíos)'!$O9,"") | G103: =IF('5. Servicio Técnico (Envíos)'!$M9="No",IFERROR(VLOOKUP('5. Servicio Técnico (Envíos)'!$A9,'1. Órdenes de Trabajo'!$A$2:$J$301,10,FALSE()),""),"")
A104: =IF('5. Servicio Técnico (Envíos)'!$M10="No",'5. Servicio Técnico (Envíos)'!$A10,"") | B104: =IF('5. Servicio Técnico (Envíos)'!$M10="No",IFERROR(VLOOKUP('5. Servicio Técnico (Envíos)'!$A10,'1. Órdenes de Trabajo'!$A$2:$E$301,5,FALSE()),""),"") | C104: =IF('5. Servicio Técnico (Envíos)'!$M10="No","Servicio técnico","") | D104: =IF('5. Servicio Técnico (Envíos)'!$M10="No",'5. Servicio Técnico (Envíos)'!$E10,"") | E104: =IF('5. Servicio Técnico (Envíos)'!$M10="No",'5. Servicio Técnico (Envíos)'!$N10,"") | F104: =IF('5. Servicio Técnico (Envíos)'!$M10="No",'5. Servicio Técnico (Envíos)'!$O10,"") | G104: =IF('5. Servicio Técnico (Envíos)'!$M10="No",IFERROR(VLOOKUP('5. Servicio Técnico (Envíos)'!$A10,'1. Órdenes de Trabajo'!$A$2:$J$301,10,FALSE()),""),"")
A105: =IF('5. Servicio Técnico (Envíos)'!$M11="No",'5. Servicio Técnico (Envíos)'!$A11,"") | B105: =IF('5. Servicio Técnico (Envíos)'!$M11="No",IFERROR(VLOOKUP('5. Servicio Técnico (Envíos)'!$A11,'1. Órdenes de Trabajo'!$A$2:$E$301,5,FALSE()),""),"") | C105: =IF('5. Servicio Técnico (Envíos)'!$M11="No","Servicio técnico","") | D105: =IF('5. Servicio Técnico (Envíos)'!$M11="No",'5. Servicio Técnico (Envíos)'!$E11,"") | E105: =IF('5. Servicio Técnico (Envíos)'!$M11="No",'5. Servicio Técnico (Envíos)'!$N11,"") | F105: =IF('5. Servicio Técnico (Envíos)'!$M11="No",'5. Servicio Técnico (Envíos)'!$O11,"") | G105: =IF('5. Servicio Técnico (Envíos)'!$M11="No",IFERROR(VLOOKUP('5. Servicio Técnico (Envíos)'!$A11,'1. Órdenes de Trabajo'!$A$2:$J$301,10,FALSE()),""),"")
A106: =IF('5. Servicio Técnico (Envíos)'!$M12="No",'5. Servicio Técnico (Envíos)'!$A12,"") | B106: =IF('5. Servicio Técnico (Envíos)'!$M12="No",IFERROR(VLOOKUP('5. Servicio Técnico (Envíos)'!$A12,'1. Órdenes de Trabajo'!$A$2:$E$301,5,FALSE()),""),"") | C106: =IF('5. Servicio Técnico (Envíos)'!$M12="No","Servicio técnico","") | D106: =IF('5. Servicio Técnico (Envíos)'!$M12="No",'5. Servicio Técnico (Envíos)'!$E12,"") | E106: =IF('5. Servicio Técnico (Envíos)'!$M12="No",'5. Servicio Técnico (Envíos)'!$N12,"") | F106: =IF('5. Servicio Técnico (Envíos)'!$M12="No",'5. Servicio Técnico (Envíos)'!$O12,"") | G106: =IF('5. Servicio Técnico (Envíos)'!$M12="No",IFERROR(VLOOKUP('5. Servicio Técnico (Envíos)'!$A12,'1. Órdenes de Trabajo'!$A$2:$J$301,10,FALSE()),""),"")
A107: =IF('5. Servicio Técnico (Envíos)'!$M13="No",'5. Servicio Técnico (Envíos)'!$A13,"") | B107: =IF('5. Servicio Técnico (Envíos)'!$M13="No",IFERROR(VLOOKUP('5. Servicio Técnico (Envíos)'!$A13,'1. Órdenes de Trabajo'!$A$2:$E$301,5,FALSE()),""),"") | C107: =IF('5. Servicio Técnico (Envíos)'!$M13="No","Servicio técnico","") | D107: =IF('5. Servicio Técnico (Envíos)'!$M13="No",'5. Servicio Técnico (Envíos)'!$E13,"") | E107: =IF('5. Servicio Técnico (Envíos)'!$M13="No",'5. Servicio Técnico (Envíos)'!$N13,"") | F107: =IF('5. Servicio Técnico (Envíos)'!$M13="No",'5. Servicio Técnico (Envíos)'!$O13,"") | G107: =IF('5. Servicio Técnico (Envíos)'!$M13="No",IFERROR(VLOOKUP('5. Servicio Técnico (Envíos)'!$A13,'1. Órdenes de Trabajo'!$A$2:$J$301,10,FALSE()),""),"")
... A135: =IF('5. Servicio Técnico (Envíos)'!$M41="No",'5. Servicio Técnico (Envíos)'!$A41,"") | B135: =IF('5. Servicio Técnico (Envíos)'!$M41="No",IFERROR(VLOOKUP('5. Servicio Técnico (Envíos)'!$A41,'1. Órdenes de Trabajo'!$A$2:$E$301,5,FALSE()),""),"") | C135: =IF('5. Servicio Técnico (Envíos)'!$M41="No","Servicio técnico","") | D135: =IF('5. Servicio Técnico (Envíos)'!$M41="No",'5. Servicio Técnico (Envíos)'!$E41,"") | E135: =IF('5. Servicio Técnico (Envíos)'!$M41="No",'5. Servicio Técnico (Envíos)'!$N41,"") | F135: =IF('5. Servicio Técnico (Envíos)'!$M41="No",'5. Servicio Técnico (Envíos)'!$O41,"") | G135: =IF('5. Servicio Técnico (Envíos)'!$M41="No",IFERROR(VLOOKUP('5. Servicio Técnico (Envíos)'!$A41,'1. Órdenes de Trabajo'!$A$2:$J$301,10,FALSE()),""),"")
A136: =IF('4. Visitas Técnicas'!$L2="No",'4. Visitas Técnicas'!$A2,"") -> 2025-121109-19-10024 | B136: =IF('4. Visitas Técnicas'!$L2="No",IFERROR(VLOOKUP('4. Visitas Técnicas'!$A2,'1. Órdenes de Trabajo'!$A$2:$E$301,5,FALSE()),""),"") -> Ventilador Mecánico | C136: =IF('4. Visitas Técnicas'!$L2="No","Visita técnica","") -> Visita técnica | D136: =IF('4. Visitas Técnicas'!$L2="No",'4. Visitas Técnicas'!$C2,"") -> DRAGER CHILE LIMITADA | E136: =IF('4. Visitas Técnicas'!$L2="No",'4. Visitas Técnicas'!$M2,"") -> Ricardo Matus Aroca | F136: =IF('4. Visitas Técnicas'!$L2="No",'4. Visitas Técnicas'!$N2,"") -> Cristián Beltrán Oviedo | G136: =IF('4. Visitas Técnicas'!$L2="No",IFERROR(VLOOKUP('4. Visitas Técnicas'!$A2,'1. Órdenes de Trabajo'!$A$2:$J$301,10,FALSE()),""),"") -> Cerrado
A137: =IF('4. Visitas Técnicas'!$L3="No",'4. Visitas Técnicas'!$A3,"") | B137: =IF('4. Visitas Técnicas'!$L3="No",IFERROR(VLOOKUP('4. Visitas Técnicas'!$A3,'1. Órdenes de Trabajo'!$A$2:$E$301,5,FALSE()),""),"") | C137: =IF('4. Visitas Técnicas'!$L3="No","Visita técnica","") | D137: =IF('4. Visitas Técnicas'!$L3="No",'4. Visitas Técnicas'!$C3,"") | E137: =IF('4. Visitas Técnicas'!$L3="No",'4. Visitas Técnicas'!$M3,"") | F137: =IF('4. Visitas Técnicas'!$L3="No",'4. Visitas Técnicas'!$N3,"") | G137: =IF('4. Visitas Técnicas'!$L3="No",IFERROR(VLOOKUP('4. Visitas Técnicas'!$A3,'1. Órdenes de Trabajo'!$A$2:$J$301,10,FALSE()),""),"")
A138: =IF('4. Visitas Técnicas'!$L4="No",'4. Visitas Técnicas'!$A4,"") | B138: =IF('4. Visitas Técnicas'!$L4="No",IFERROR(VLOOKUP('4. Visitas Técnicas'!$A4,'1. Órdenes de Trabajo'!$A$2:$E$301,5,FALSE()),""),"") | C138: =IF('4. Visitas Técnicas'!$L4="No","Visita técnica","") | D138: =IF('4. Visitas Técnicas'!$L4="No",'4. Visitas Técnicas'!$C4,"") | E138: =IF('4. Visitas Técnicas'!$L4="No",'4. Visitas Técnicas'!$M4,"") | F138: =IF('4. Visitas Técnicas'!$L4="No",'4. Visitas Técnicas'!$N4,"") | G138: =IF('4. Visitas Técnicas'!$L4="No",IFERROR(VLOOKUP('4. Visitas Técnicas'!$A4,'1. Órdenes de Trabajo'!$A$2:$J$301,10,FALSE()),""),"")
A139: =IF('4. Visitas Técnicas'!$L5="No",'4. Visitas Técnicas'!$A5,"") | B139: =IF('4. Visitas Técnicas'!$L5="No",IFERROR(VLOOKUP('4. Visitas Técnicas'!$A5,'1. Órdenes de Trabajo'!$A$2:$E$301,5,FALSE()),""),"") | C139: =IF('4. Visitas Técnicas'!$L5="No","Visita técnica","") | D139: =IF('4. Visitas Técnicas'!$L5="No",'4. Visitas Técnicas'!$C5,"") | E139: =IF('4. Visitas Técnicas'!$L5="No",'4. Visitas Técnicas'!$M5,"") | F139: =IF('4. Visitas Técnicas'!$L5="No",'4. Visitas Técnicas'!$N5,"") | G139: =IF('4. Visitas Técnicas'!$L5="No",IFERROR(VLOOKUP('4. Visitas Técnicas'!$A5,'1. Órdenes de Trabajo'!$A$2:$J$301,10,FALSE()),""),"")
...

Sheet MP Carta 2026
A1: Programa de Mantención Preventiva 2026 — Carta de ejecución
A2: Un equipo por fila (los 966 de la base). Marca el código del mes en cada celda: X programada · E ejecutada · C2/C3 no ejecutada por falla · R reprogramada · B baja. La identidad del equipo se hereda de la hoja Equipos.
A3: N° Inventario | B3: Equipo | C3: Servicio | D3: Ubicación | E3: Marca | F3: Modelo | G3: Serie | H3: Periodicidad | I3: Ene | J3: Feb | K3: Mar | L3: Abr | M3: May | N3: Jun | O3: Jul | P3: Ago | Q3: Sep | R3: Oct | S3: Nov | T3: Dic | U3: Programadas | V3: Ejecutadas | W3: Pendientes | X3: x Correctivo | Y3: Atrasadas | Z3: % avance
A4: =Equipos!C2 -> 2-115361 | B4: =Equipos!D2 -> Incubadora | C4: =Equipos!E2 -> Neonatología | D4: =Equipos!G2 -> UTI 1/2 | E4: =Equipos!I2 -> DRAGER | F4: =Equipos!J2 -> CALEO | G4: =Equipos!K2 -> ASJL-0008 | J4: E | M4: E | U4: =V4+W4+X4+COUNTIF(I4:T4,"R") -> 2 | V4: =COUNTIF(I4:T4,"E") -> 2 | W4: =COUNTIF(I4:T4,"X") -> 0 | X4: =COUNTIF(I4:T4,"C2")+COUNTIF(I4:T4,"C3") -> 0 | Y4: =SUMPRODUCT((I4:INDEX(I4:T4,MONTH(TODAY()))="X")*1) -> 0 | Z4: =IFERROR(V4/U4,"") -> 1
A5: =Equipos!C3 -> 2-116070 | B5: =Equipos!D3 -> Incubadora | C5: =Equipos!E3 -> Neonatología | D5: =Equipos!G3 -> SALA EQUIPOS | E5: =Equipos!I3 -> GENERAL ELECTRIC | F5: =Equipos!J3 -> GIRAFFE OMNIBED CARESTATION | G5: =Equipos!K3 -> TABX62307 | J5: E | M5: E | U5: =V5+W5+X5+COUNTIF(I5:T5,"R") -> 2 | V5: =COUNTIF(I5:T5,"E") -> 2 | W5: =COUNTIF(I5:T5,"X") -> 0 | X5: =COUNTIF(I5:T5,"C2")+COUNTIF(I5:T5,"C3") -> 0 | Y5: =SUMPRODUCT((I5:INDEX(I5:T5,MONTH(TODAY()))="X")*1) -> 0 | Z5: =IFERROR(V5/U5,"") -> 1
A6: =Equipos!C4 -> 2-116071 | B6: =Equipos!D4 -> Incubadora | C6: =Equipos!E4 -> Neonatología | D6: =Equipos!G4 -> UCI 16 | E6: =Equipos!I4 -> GENERAL ELECTRIC | F6: =Equipos!J4 -> GIRAFFE OMNIBED CARESTATION | G6: =Equipos!K4 -> TABX62308 | J6: E | M6: E | U6: =V6+W6+X6+COUNTIF(I6:T6,"R") -> 2 | V6: =COUNTIF(I6:T6,"E") -> 2 | W6: =COUNTIF(I6:T6,"X") -> 0 | X6: =COUNTIF(I6:T6,"C2")+COUNTIF(I6:T6,"C3") -> 0 | Y6: =SUMPRODUCT((I6:INDEX(I6:T6,MONTH(TODAY()))="X")*1) -> 0 | Z6: =IFERROR(V6/U6,"") -> 1
A7: =Equipos!C5 -> 2-116018 | B7: =Equipos!D5 -> Incubadora | C7: =Equipos!E5 -> Neonatología | D7: =Equipos!G5 -> UTI 1/4 | E7: =Equipos!I5 -> DRAGER | F7: =Equipos!J5 -> CALEO | G7: =Equipos!K5 -> ASHM-0118 | J7: E | M7: E | N7: E | U7: =V7+W7+X7+COUNTIF(I7:T7,"R") -> 3 | V7: =COUNTIF(I7:T7,"E") -> 3 | W7: =COUNTIF(I7:T7,"X") -> 0 | X7: =COUNTIF(I7:T7,"C2")+COUNTIF(I7:T7,"C3") -> 0 | Y7: =SUMPRODUCT((I7:INDEX(I7:T7,MONTH(TODAY()))="X")*1) -> 0 | Z7: =IFERROR(V7/U7,"") -> 1
A8: =Equipos!C6 -> 2-116072 | B8: =Equipos!D6 -> Incubadora | C8: =Equipos!E6 -> Neonatología | D8: =Equipos!G6 -> UCI 4 | E8: =Equipos!I6 -> GENERAL ELECTRIC | F8: =Equipos!J6 -> GIRAFFE OMNIBED CARESTATION | G8: =Equipos!K6 -> TABX62309 | J8: E | M8: X | U8: =V8+W8+X8+COUNTIF(I8:T8,"R") -> 2 | V8: =COUNTIF(I8:T8,"E") -> 1 | W8: =COUNTIF(I8:T8,"X") -> 1 | X8: =COUNTIF(I8:T8,"C2")+COUNTIF(I8:T8,"C3") -> 0 | Y8: =SUMPRODUCT((I8:INDEX(I8:T8,MONTH(TODAY()))="X")*1) -> 1 | Z8: =IFERROR(V8/U8,"") -> 0.5
A9: =Equipos!C7 -> 0 | B9: =Equipos!D7 -> 0 | C9: =Equipos!E7 -> 0 | D9: =Equipos!G7 -> 0 | E9: =Equipos!I7 -> 0 | F9: =Equipos!J7 -> 0 | G9: =Equipos!K7 -> 0 | U9: =V9+W9+X9+COUNTIF(I9:T9,"R") -> 0 | V9: =COUNTIF(I9:T9,"E") -> 0 | W9: =COUNTIF(I9:T9,"X") -> 0 | X9: =COUNTIF(I9:T9,"C2")+COUNTIF(I9:T9,"C3") -> 0 | Y9: =SUMPRODUCT((I9:INDEX(I9:T9,MONTH(TODAY()))="X")*1) -> 0 | Z9: =IFERROR(V9/U9,"")
